Workbook

Sheet Hypothèses
A1: MODÈLE DE PROJECTION FINANCIÈRE — NIVRA TELECOM 2026-2028
A2: Généré le 2026-06-13 | Cellules bleues = inputs modifiables
A4: BASE — Paramètres de départ | B4: Valeur | C4: Note
A5: Abonnés actuels (mois 0) | B5: 13 | C5: Point de départ au 1er janvier 2026
A6: ARPU moyen ($/abonné/mois) | B6: 42 | C6: Average Revenue Per User — prépayé Québec
A7: Churn mensuel (%) | B7: 0.025 | C7: Taux de désabonnement mensuel estimé
A9: SCÉNARIOS DE CROISSANCE | B9: Nouveaux abonnés/mois
A10: Pessimiste | B10: 50 | C10: Marché difficile, peu de marketing
A11: Base | B11: 120 | C11: Scénario de référence
A12: Optimiste | B12: 250 | C12: Expansion agressive, bouche-à-oreille fort
A14: COÛTS FIXES MENSUELS | B14: Montant ($)
A15: Infrastructure / réseau wholesale | B15: 5000
A16: Salaires et contrats | B16: 8000
A17: Marketing et acquisition | B17: 2000
A18: Admin / légal / compliance CRTC | B18: 1500
A19: Technologie (AWS, Supabase, SaaS) | B19: 500
A20: Autres dépenses opérationnelles | B20: 1000
A21: TOTAL COÛTS FIXES MENSUELS | B21: =SUM(B15:B20)
A23: COÛTS VARIABLES | B23: Montant
A24: Coût acquisition / SIM ($/nouvel abonné) | B24: 15 | C24: Carte SIM + activation
A25: Coût réseau variable ($/abonné/mois) | B25: 8 | C25: Coût MVNO / réseau hôte
A27: Cellules bleues = Inputs modifiables | Noir = Formules calculées | Jaune = Totaux

Sheet Projection 36 mois
A1: PROJECTION FINANCIÈRE 36 MOIS — NIVRA TELECOM (formules liées à l'onglet Hypothèses)
C2: ▼ PESSIMISTE (50 nouveaux/mois) | M2: ▼ BASE (120 nouveaux/mois) | W2: ▼ OPTIMISTE (250 nouveaux/mois)
A3: Mois | B3: Date | C3: Nouveaux | D3: Churnés | E3: Abonnés | F3: Revenus | G3: Coût acq. | H3: Coût réseau | I3: Fixes | J3: EBITDA | K3: EBITDA cum. | M3: Nouveaux | N3: Churnés | O3: Abonnés | P3: Revenus | Q3: Coût acq. | R3: Coût réseau | S3: Fixes | T3: EBITDA | U3: EBITDA cum. | W3: Nouveaux | X3: Churnés | Y3: Abonnés | Z3: Revenus | AA3: Coût acq. | AB3: Coût réseau | AC3: Fixes | AD3: EBITDA | AE3: EBITDA cum.
A4: 1 | B4: 46023.208 | C4: =Hypothèses!B10 | D4: =ROUND(Hypothèses!B5*Hypothèses!$B$7,0) | E4: =Hypothèses!B5+C4-D4 | F4: =E4*Hypothèses!$B$6 | G4: =C4*Hypothèses!$B$24 | H4: =E4*Hypothèses!$B$25 | I4: =Hypothèses!$B$21 | J4: =F4-G4-H4-I4 | K4: =J4 | M4: =Hypothèses!B11 | N4: =ROUND(Hypothèses!B5*Hypothèses!$B$7,0) | O4: =Hypothèses!B5+M4-N4 | P4: =O4*Hypothèses!$B$6 | Q4: =M4*Hypothèses!$B$24 | R4: =O4*Hypothèses!$B$25 | S4: =Hypothèses!$B$21 | T4: =P4-Q4-R4-S4 | U4: =T4 | W4: =Hypothèses!B12 | X4: =ROUND(Hypothèses!B5*Hypothèses!$B$7,0) | Y4: =Hypothèses!B5+W4-X4 | Z4: =Y4*Hypothèses!$B$6 | AA4: =W4*Hypothèses!$B$24 | AB4: =Y4*Hypothèses!$B$25 | AC4: =Hypothèses!$B$21 | AD4: =Z4-AA4-AB4-AC4 | AE4: =AD4
A5: 2 | B5: 46054.208 | C5: =Hypothèses!B10 | D5: =ROUND(E4*Hypothèses!$B$7,0) | E5: =E4+C5-D5 | F5: =E5*Hypothèses!$B$6 | G5: =C5*Hypothèses!$B$24 | H5: =E5*Hypothèses!$B$25 | I5: =Hypothèses!$B$21 | J5: =F5-G5-H5-I5 | K5: =K4+J5 | M5: =Hypothèses!B11 | N5: =ROUND(O4*Hypothèses!$B$7,0) | O5: =O4+M5-N5 | P5: =O5*Hypothèses!$B$6 | Q5: =M5*Hypothèses!$B$24 | R5: =O5*Hypothèses!$B$25 | S5: =Hypothèses!$B$21 | T5: =P5-Q5-R5-S5 | U5: =U4+T5 | W5: =Hypothèses!B12 | X5: =ROUND(Y4*Hypothèses!$B$7,0) | Y5: =Y4+W5-X5 | Z5: =Y5*Hypothèses!$B$6 | AA5: =W5*Hypothèses!$B$24 | AB5: =Y5*Hypothèses!$B$25 | AC5: =Hypothèses!$B$21 | AD5: =Z5-AA5-AB5-AC5 | AE5: =AE4+AD5
A6: 3 | B6: 46082.208 | C6: =Hypothèses!B10 | D6: =ROUND(E5*Hypothèses!$B$7,0) | E6: =E5+C6-D6 | F6: =E6*Hypothèses!$B$6 | G6: =C6*Hypothèses!$B$24 | H6: =E6*Hypothèses!$B$25 | I6: =Hypothèses!$B$21 | J6: =F6-G6-H6-I6 | K6: =K5+J6 | M6: =Hypothèses!B11 | N6: =ROUND(O5*Hypothèses!$B$7,0) | O6: =O5+M6-N6 | P6: =O6*Hypothèses!$B$6 | Q6: =M6*Hypothèses!$B$24 | R6: =O6*Hypothèses!$B$25 | S6: =Hypothèses!$B$21 | T6: =P6-Q6-R6-S6 | U6: =U5+T6 | W6: =Hypothèses!B12 | X6: =ROUND(Y5*Hypothèses!$B$7,0) | Y6: =Y5+W6-X6 | Z6: =Y6*Hypothèses!$B$6 | AA6: =W6*Hypothèses!$B$24 | AB6: =Y6*Hypothèses!$B$25 | AC6: =Hypothèses!$B$21 | AD6: =Z6-AA6-AB6-AC6 | AE6: =AE5+AD6
A7: 4 | B7: 46113.167 | C7: =Hypothèses!B10 | D7: =ROUND(E6*Hypothèses!$B$7,0) | E7: =E6+C7-D7 | F7: =E7*Hypothèses!$B$6 | G7: =C7*Hypothèses!$B$24 | H7: =E7*Hypothèses!$B$25 | I7: =Hypothèses!$B$21 | J7: =F7-G7-H7-I7 | K7: =K6+J7 | M7: =Hypothèses!B11 | N7: =ROUND(O6*Hypothèses!$B$7,0) | O7: =O6+M7-N7 | P7: =O7*Hypothèses!$B$6 | Q7: =M7*Hypothèses!$B$24 | R7: =O7*Hypothèses!$B$25 | S7: =Hypothèses!$B$21 | T7: =P7-Q7-R7-S7 | U7: =U6+T7 | W7: =Hypothèses!B12 | X7: =ROUND(Y6*Hypothèses!$B$7,0) | Y7: =Y6+W7-X7 | Z7: =Y7*Hypothèses!$B$6 | AA7: =W7*Hypothèses!$B$24 | AB7: =Y7*Hypothèses!$B$25 | AC7: =Hypothèses!$B$21 | AD7: =Z7-AA7-AB7-AC7 | AE7: =AE6+AD7
A8: 5 | B8: 46143.167 | C8: =Hypothèses!B10 | D8: =ROUND(E7*Hypothèses!$B$7,0) | E8: =E7+C8-D8 | F8: =E8*Hypothèses!$B$6 | G8: =C8*Hypothèses!$B$24 | H8: =E8*Hypothèses!$B$25 | I8: =Hypothèses!$B$21 | J8: =F8-G8-H8-I8 | K8: =K7+J8 | M8: =Hypothèses!B11 | N8: =ROUND(O7*Hypothèses!$B$7,0) | O8: =O7+M8-N8 | P8: =O8*Hypothèses!$B$6 | Q8: =M8*Hypothèses!$B$24 | R8: =O8*Hypothèses!$B$25 | S8: =Hypothèses!$B$21 | T8: =P8-Q8-R8-S8 | U8: =U7+T8 | W8: =Hypothèses!B12 | X8: =ROUND(Y7*Hypothèses!$B$7,0) | Y8: =Y7+W8-X8 | Z8: =Y8*Hypothèses!$B$6 | AA8: =W8*Hypothèses!$B$24 | AB8: =Y8*Hypothèses!$B$25 | AC8: =Hypothèses!$B$21 | AD8: =Z8-AA8-AB8-AC8 | AE8: =AE7+AD8
A9: 6 | B9: 46174.167 | C9: =Hypothèses!B10 | D9: =ROUND(E8*Hypothèses!$B$7,0) | E9: =E8+C9-D9 | F9: =E9*Hypothèses!$B$6 | G9: =C9*Hypothèses!$B$24 | H9: =E9*Hypothèses!$B$25 | I9: =Hypothèses!$B$21 | J9: =F9-G9-H9-I9 | K9: =K8+J9 | M9: =Hypothèses!B11 | N9: =ROUND(O8*Hypothèses!$B$7,0) | O9: =O8+M9-N9 | P9: =O9*Hypothèses!$B$6 | Q9: =M9*Hypothèses!$B$24 | R9: =O9*Hypothèses!$B$25 | S9: =Hypothèses!$B$21 | T9: =P9-Q9-R9-S9 | U9: =U8+T9 | W9: =Hypothèses!B12 | X9: =ROUND(Y8*Hypothèses!$B$7,0) | Y9: =Y8+W9-X9 | Z9: =Y9*Hypothèses!$B$6 | AA9: =W9*Hypothèses!$B$24 | AB9: =Y9*Hypothèses!$B$25 | AC9: =Hypothèses!$B$21 | AD9: =Z9-AA9-AB9-AC9 | AE9: =AE8+AD9
A10: 7 | B10: 46204.167 | C10: =Hypothèses!B10 | D10: =ROUND(E9*Hypothèses!$B$7,0) | E10: =E9+C10-D10 | F10: =E10*Hypothèses!$B$6 | G10: =C10*Hypothèses!$B$24 | H10: =E10*Hypothèses!$B$25 | I10: =Hypothèses!$B$21 | J10: =F10-G10-H10-I10 | K10: =K9+J10 | M10: =Hypothèses!B11 | N10: =ROUND(O9*Hypothèses!$B$7,0) | O10: =O9+M10-N10 | P10: =O10*Hypothèses!$B$6 | Q10: =M10*Hypothèses!$B$24 | R10: =O10*Hypothèses!$B$25 | S10: =Hypothèses!$B$21 | T10: =P10-Q10-R10-S10 | U10: =U9+T10 | W10: =Hypothèses!B12 | X10: =ROUND(Y9*Hypothèses!$B$7,0) | Y10: =Y9+W10-X10 | Z10: =Y10*Hypothèses!$B$6 | AA10: =W10*Hypothèses!$B$24 | AB10: =Y10*Hypothèses!$B$25 | AC10: =Hypothèses!$B$21 | AD10: =Z10-AA10-AB10-AC10 | AE10: =AE9+AD10
A11: 8 | B11: 46235.167 | C11: =Hypothèses!B10 | D11: =ROUND(E10*Hypothèses!$B$7,0) | E11: =E10+C11-D11 | F11: =E11*Hypothèses!$B$6 | G11: =C11*Hypothèses!$B$24 | H11: =E11*Hypothèses!$B$25 | I11: =Hypothèses!$B$21 | J11: =F11-G11-H11-I11 | K11: =K10+J11 | M11: =Hypothèses!B11 | N11: =ROUND(O10*Hypothèses!$B$7,0) | O11: =O10+M11-N11 | P11: =O11*Hypothèses!$B$6 | Q11: =M11*Hypothèses!$B$24 | R11: =O11*Hypothèses!$B$25 | S11: =Hypothèses!$B$21 | T11: =P11-Q11-R11-S11 | U11: =U10+T11 | W11: =Hypothèses!B12 | X11: =ROUND(Y10*Hypothèses!$B$7,0) | Y11: =Y10+W11-X11 | Z11: =Y11*Hypothèses!$B$6 | AA11: =W11*Hypothèses!$B$24 | AB11: =Y11*Hypothèses!$B$25 | AC11: =Hypothèses!$B$21 | AD11: =Z11-AA11-AB11-AC11 | AE11: =AE10+AD11
A12: 9 | B12: 46266.167 | C12: =Hypothèses!B10 | D12: =ROUND(E11*Hypothèses!$B$7,0) | E12: =E11+C12-D12 | F12: =E12*Hypothèses!$B$6 | G12: =C12*Hypothèses!$B$24 | H12: =E12*Hypothèses!$B$25 | I12: =Hypothèses!$B$21 | J12: =F12-G12-H12-I12 | K12: =K11+J12 | M12: =Hypothèses!B11 | N12: =ROUND(O11*Hypothèses!$B$7,0) | O12: =O11+M12-N12 | P12: =O12*Hypothèses!$B$6 | Q12: =M12*Hypothèses!$B$24 | R12: =O12*Hypothèses!$B$25 | S12: =Hypothèses!$B$21 | T12: =P12-Q12-R12-S12 | U12: =U11+T12 | W12: =Hypothèses!B12 | X12: =ROUND(Y11*Hypothèses!$B$7,0) | Y12: =Y11+W12-X12 | Z12: =Y12*Hypothèses!$B$6 | AA12: =W12*Hypothèses!$B$24 | AB12: =Y12*Hypothèses!$B$25 | AC12: =Hypothèses!$B$21 | AD12: =Z12-AA12-AB12-AC12 | AE12: =AE11+AD12
A13: 10 | B13: 46296.167 | C13: =Hypothèses!B10 | D13: =ROUND(E12*Hypothèses!$B$7,0) | E13: =E12+C13-D13 | F13: =E13*Hypothèses!$B$6 | G13: =C13*Hypothèses!$B$24 | H13: =E13*Hypothèses!$B$25 | I13: =Hypothèses!$B$21 | J13: =F13-G13-H13-I13 | K13: =K12+J13 | M13: =Hypothèses!B11 | N13: =ROUND(O12*Hypothèses!$B$7,0) | O13: =O12+M13-N13 | P13: =O13*Hypothèses!$B$6 | Q13: =M13*Hypothèses!$B$24 | R13: =O13*Hypothèses!$B$25 | S13: =Hypothèses!$B$21 | T13: =P13-Q13-R13-S13 | U13: =U12+T13 | W13: =Hypothèses!B12 | X13: =ROUND(Y12*Hypothèses!$B$7,0) | Y13: =Y12+W13-X13 | Z13: =Y13*Hypothèses!$B$6 | AA13: =W13*Hypothèses!$B$24 | AB13: =Y13*Hypothèses!$B$25 | AC13: =Hypothèses!$B$21 | AD13: =Z13-AA13-AB13-AC13 | AE13: =AE12+AD13
A14: 11 | B14: 46327.167 | C14: =Hypothèses!B10 | D14: =ROUND(E13*Hypothèses!$B$7,0) | E14: =E13+C14-D14 | F14: =E14*Hypothèses!$B$6 | G14: =C14*Hypothèses!$B$24 | H14: =E14*Hypothèses!$B$25 | I14: =Hypothèses!$B$21 | J14: =F14-G14-H14-I14 | K14: =K13+J14 | M14: =Hypothèses!B11 | N14: =ROUND(O13*Hypothèses!$B$7,0) | O14: =O13+M14-N14 | P14: =O14*Hypothèses!$B$6 | Q14: =M14*Hypothèses!$B$24 | R14: =O14*Hypothèses!$B$25 | S14: =Hypothèses!$B$21 | T14: =P14-Q14-R14-S14 | U14: =U13+T14 | W14: =Hypothèses!B12 | X14: =ROUND(Y13*Hypothèses!$B$7,0) | Y14: =Y13+W14-X14 | Z14: =Y14*Hypothèses!$B$6 | AA14: =W14*Hypothèses!$B$24 | AB14: =Y14*Hypothèses!$B$25 | AC14: =Hypothèses!$B$21 | AD14: =Z14-AA14-AB14-AC14 | AE14: =AE13+AD14
A15: 12 | B15: 46357.208 | C15: =Hypothèses!B10 | D15: =ROUND(E14*Hypothèses!$B$7,0) | E15: =E14+C15-D15 | F15: =E15*Hypothèses!$B$6 | G15: =C15*Hypothèses!$B$24 | H15: =E15*Hypothèses!$B$25 | I15: =Hypothèses!$B$21 | J15: =F15-G15-H15-I15 | K15: =K14+J15 | M15: =Hypothèses!B11 | N15: =ROUND(O14*Hypothèses!$B$7,0) | O15: =O14+M15-N15 | P15: =O15*Hypothèses!$B$6 | Q15: =M15*Hypothèses!$B$24 | R15: =O15*Hypothèses!$B$25 | S15: =Hypothèses!$B$21 | T15: =P15-Q15-R15-S15 | U15: =U14+T15 | W15: =Hypothèses!B12 | X15: =ROUND(Y14*Hypothèses!$B$7,0) | Y15: =Y14+W15-X15 | Z15: =Y15*Hypothèses!$B$6 | AA15: =W15*Hypothèses!$B$24 | AB15: =Y15*Hypothèses!$B$25 | AC15: =Hypothèses!$B$21 | AD15: =Z15-AA15-AB15-AC15 | AE15: =AE14+AD15
A16: 13 | B16: 46388.208 | C16: =Hypothèses!B10 | D16: =ROUND(E15*Hypothèses!$B$7,0) | E16: =E15+C16-D16 | F16: =E16*Hypothèses!$B$6 | G16: =C16*Hypothèses!$B$24 | H16: =E16*Hypothèses!$B$25 | I16: =Hypothèses!$B$21 | J16: =F16-G16-H16-I16 | K16: =K15+J16 | M16: =Hypothèses!B11 | N16: =ROUND(O15*Hypothèses!$B$7,0) | O16: =O15+M16-N16 | P16: =O16*Hypothèses!$B$6 | Q16: =M16*Hypothèses!$B$24 | R16: =O16*Hypothèses!$B$25 | S16: =Hypothèses!$B$21 | T16: =P16-Q16-R16-S16 | U16: =U15+T16 | W16: =Hypothèses!B12 | X16: =ROUND(Y15*Hypothèses!$B$7,0) | Y16: =Y15+W16-X16 | Z16: =Y16*Hypothèses!$B$6 | AA16: =W16*Hypothèses!$B$24 | AB16: =Y16*Hypothèses!$B$25 | AC16: =Hypothèses!$B$21 | AD16: =Z16-AA16-AB16-AC16 | AE16: =AE15+AD16
A17: 14 | B17: 46419.208 | C17: =Hypothèses!B10 | D17: =ROUND(E16*Hypothèses!$B$7,0) | E17: =E16+C17-D17 | F17: =E17*Hypothèses!$B$6 | G17: =C17*Hypothèses!$B$24 | H17: =E17*Hypothèses!$B$25 | I17: =Hypothèses!$B$21 | J17: =F17-G17-H17-I17 | K17: =K16+J17 | M17: =Hypothèses!B11 | N17: =ROUND(O16*Hypothèses!$B$7,0) | O17: =O16+M17-N17 | P17: =O17*Hypothèses!$B$6 | Q17: =M17*Hypothèses!$B$24 | R17: =O17*Hypothèses!$B$25 | S17: =Hypothèses!$B$21 | T17: =P17-Q17-R17-S17 | U17: =U16+T17 | W17: =Hypothèses!B12 | X17: =ROUND(Y16*Hypothèses!$B$7,0) | Y17: =Y16+W17-X17 | Z17: =Y17*Hypothèses!$B$6 | AA17: =W17*Hypothèses!$B$24 | AB17: =Y17*Hypothèses!$B$25 | AC17: =Hypothèses!$B$21 | AD17: =Z17-AA17-AB17-AC17 | AE17: =AE16+AD17
A18: 15 | B18: 46447.208 | C18: =Hypothèses!B10 | D18: =ROUND(E17*Hypothèses!$B$7,0) | E18: =E17+C18-D18 | F18: =E18*Hypothèses!$B$6 | G18: =C18*Hypothèses!$B$24 | H18: =E18*Hypothèses!$B$25 | I18: =Hypothèses!$B$21 | J18: =F18-G18-H18-I18 | K18: =K17+J18 | M18: =Hypothèses!B11 | N18: =ROUND(O17*Hypothèses!$B$7,0) | O18: =O17+M18-N18 | P18: =O18*Hypothèses!$B$6 | Q18: =M18*Hypothèses!$B$24 | R18: =O18*Hypothèses!$B$25 | S18: =Hypothèses!$B$21 | T18: =P18-Q18-R18-S18 | U18: =U17+T18 | W18: =Hypothèses!B12 | X18: =ROUND(Y17*Hypothèses!$B$7,0) | Y18: =Y17+W18-X18 | Z18: =Y18*Hypothèses!$B$6 | AA18: =W18*Hypothèses!$B$24 | AB18: =Y18*Hypothèses!$B$25 | AC18: =Hypothèses!$B$21 | AD18: =Z18-AA18-AB18-AC18 | AE18: =AE17+AD18
A19: 16 | B19: 46478.167 | C19: =Hypothèses!B10 | D19: =ROUND(E18*Hypothèses!$B$7,0) | E19: =E18+C19-D19 | F19: =E19*Hypothèses!$B$6 | G19: =C19*Hypothèses!$B$24 | H19: =E19*Hypothèses!$B$25 | I19: =Hypothèses!$B$21 | J19: =F19-G19-H19-I19 | K19: =K18+J19 | M19: =Hypothèses!B11 | N19: =ROUND(O18*Hypothèses!$B$7,0) | O19: =O18+M19-N19 | P19: =O19*Hypothèses!$B$6 | Q19: =M19*Hypothèses!$B$24 | R19: =O19*Hypothèses!$B$25 | S19: =Hypothèses!$B$21 | T19: =P19-Q19-R19-S19 | U19: =U18+T19 | W19: =Hypothèses!B12 | X19: =ROUND(Y18*Hypothèses!$B$7,0) | Y19: =Y18+W19-X19 | Z19: =Y19*Hypothèses!$B$6 | AA19: =W19*Hypothèses!$B$24 | AB19: =Y19*Hypothèses!$B$25 | AC19: =Hypothèses!$B$21 | AD19: =Z19-AA19-AB19-AC19 | AE19: =AE18+AD19
A20: 17 | B20: 46508.167 | C20: =Hypothèses!B10 | D20: =ROUND(E19*Hypothèses!$B$7,0) | E20: =E19+C20-D20 | F20: =E20*Hypothèses!$B$6 | G20: =C20*Hypothèses!$B$24 | H20: =E20*Hypothèses!$B$25 | I20: =Hypothèses!$B$21 | J20: =F20-G20-H20-I20 | K20: =K19+J20 | M20: =Hypothèses!B11 | N20: =ROUND(O19*Hypothèses!$B$7,0) | O20: =O19+M20-N20 | P20: =O20*Hypothèses!$B$6 | Q20: =M20*Hypothèses!$B$24 | R20: =O20*Hypothèses!$B$25 | S20: =Hypothèses!$B$21 | T20: =P20-Q20-R20-S20 | U20: =U19+T20 | W20: =Hypothèses!B12 | X20: =ROUND(Y19*Hypothèses!$B$7,0) | Y20: =Y19+W20-X20 | Z20: =Y20*Hypothèses!$B$6 | AA20: =W20*Hypothèses!$B$24 | AB20: =Y20*Hypothèses!$B$25 | AC20: =Hypothèses!$B$21 | AD20: =Z20-AA20-AB20-AC20 | AE20: =AE19+AD20
A21: 18 | B21: 46539.167 | C21: =Hypothèses!B10 | D21: =ROUND(E20*Hypothèses!$B$7,0) | E21: =E20+C21-D21 | F21: =E21*Hypothèses!$B$6 | G21: =C21*Hypothèses!$B$24 | H21: =E21*Hypothèses!$B$25 | I21: =Hypothèses!$B$21 | J21: =F21-G21-H21-I21 | K21: =K20+J21 | M21: =Hypothèses!B11 | N21: =ROUND(O20*Hypothèses!$B$7,0) | O21: =O20+M21-N21 | P21: =O21*Hypothèses!$B$6 | Q21: =M21*Hypothèses!$B$24 | R21: =O21*Hypothèses!$B$25 | S21: =Hypothèses!$B$21 | T21: =P21-Q21-R21-S21 | U21: =U20+T21 | W21: =Hypothèses!B12 | X21: =ROUND(Y20*Hypothèses!$B$7,0) | Y21: =Y20+W21-X21 | Z21: =Y21*Hypothèses!$B$6 | AA21: =W21*Hypothèses!$B$24 | AB21: =Y21*Hypothèses!$B$25 | AC21: =Hypothèses!$B$21 | AD21: =Z21-AA21-AB21-AC21 | AE21: =AE20+AD21
A22: 19 | B22: 46569.167 | C22: =Hypothèses!B10 | D22: =ROUND(E21*Hypothèses!$B$7,0) | E22: =E21+C22-D22 | F22: =E22*Hypothèses!$B$6 | G22: =C22*Hypothèses!$B$24 | H22: =E22*Hypothèses!$B$25 | I22: =Hypothèses!$B$21 | J22: =F22-G22-H22-I22 | K22: =K21+J22 | M22: =Hypothèses!B11 | N22: =ROUND(O21*Hypothèses!$B$7,0) | O22: =O21+M22-N22 | P22: =O22*Hypothèses!$B$6 | Q22: =M22*Hypothèses!$B$24 | R22: =O22*Hypothèses!$B$25 | S22: =Hypothèses!$B$21 | T22: =P22-Q22-R22-S22 | U22: =U21+T22 | W22: =Hypothèses!B12 | X22: =ROUND(Y21*Hypothèses!$B$7,0) | Y22: =Y21+W22-X22 | Z22: =Y22*Hypothèses!$B$6 | AA22: =W22*Hypothèses!$B$24 | AB22: =Y22*Hypothèses!$B$25 | AC22: =Hypothèses!$B$21 | AD22: =Z22-AA22-AB22-AC22 | AE22: =AE21+AD22
A23: 20 | B23: 46600.167 | C23: =Hypothèses!B10 | D23: =ROUND(E22*Hypothèses!$B$7,0) | E23: =E22+C23-D23 | F23: =E23*Hypothèses!$B$6 | G23: =C23*Hypothèses!$B$24 | H23: =E23*Hypothèses!$B$25 | I23: =Hypothèses!$B$21 | J23: =F23-G23-H23-I23 | K23: =K22+J23 | M23: =Hypothèses!B11 | N23: =ROUND(O22*Hypothèses!$B$7,0) | O23: =O22+M23-N23 | P23: =O23*Hypothèses!$B$6 | Q23: =M23*Hypothèses!$B$24 | R23: =O23*Hypothèses!$B$25 | S23: =Hypothèses!$B$21 | T23: =P23-Q23-R23-S23 | U23: =U22+T23 | W23: =Hypothèses!B12 | X23: =ROUND(Y22*Hypothèses!$B$7,0) | Y23: =Y22+W23-X23 | Z23: =Y23*Hypothèses!$B$6 | AA23: =W23*Hypothèses!$B$24 | AB23: =Y23*Hypothèses!$B$25 | AC23: =Hypothèses!$B$21 | AD23: =Z23-AA23-AB23-AC23 | AE23: =AE22+AD23
A24: 21 | B24: 46631.167 | C24: =Hypothèses!B10 | D24: =ROUND(E23*Hypothèses!$B$7,0) | E24: =E23+C24-D24 | F24: =E24*Hypothèses!$B$6 | G24: =C24*Hypothèses!$B$24 | H24: =E24*Hypothèses!$B$25 | I24: =Hypothèses!$B$21 | J24: =F24-G24-H24-I24 | K24: =K23+J24 | M24: =Hypothèses!B11 | N24: =ROUND(O23*Hypothèses!$B$7,0) | O24: =O23+M24-N24 | P24: =O24*Hypothèses!$B$6 | Q24: =M24*Hypothèses!$B$24 | R24: =O24*Hypothèses!$B$25 | S24: =Hypothèses!$B$21 | T24: =P24-Q24-R24-S24 | U24: =U23+T24 | W24: =Hypothèses!B12 | X24: =ROUND(Y23*Hypothèses!$B$7,0) | Y24: =Y23+W24-X24 | Z24: =Y24*Hypothèses!$B$6 | AA24: =W24*Hypothèses!$B$24 | AB24: =Y24*Hypothèses!$B$25 | AC24: =Hypothèses!$B$21 | AD24: =Z24-AA24-AB24-AC24 | AE24: =AE23+AD24
A25: 22 | B25: 46661.167 | C25: =Hypothèses!B10 | D25: =ROUND(E24*Hypothèses!$B$7,0) | E25: =E24+C25-D25 | F25: =E25*Hypothèses!$B$6 | G25: =C25*Hypothèses!$B$24 | H25: =E25*Hypothèses!$B$25 | I25: =Hypothèses!$B$21 | J25: =F25-G25-H25-I25 | K25: =K24+J25 | M25: =Hypothèses!B11 | N25: =ROUND(O24*Hypothèses!$B$7,0) | O25: =O24+M25-N25 | P25: =O25*Hypothèses!$B$6 | Q25: =M25*Hypothèses!$B$24 | R25: =O25*Hypothèses!$B$25 | S25: =Hypothèses!$B$21 | T25: =P25-Q25-R25-S25 | U25: =U24+T25 | W25: =Hypothèses!B12 | X25: =ROUND(Y24*Hypothèses!$B$7,0) | Y25: =Y24+W25-X25 | Z25: =Y25*Hypothèses!$B$6 | AA25: =W25*Hypothèses!$B$24 | AB25: =Y25*Hypothèses!$B$25 | AC25: =Hypothèses!$B$21 | AD25: =Z25-AA25-AB25-AC25 | AE25: =AE24+AD25
A26: 23 | B26: 46692.167 | C26: =Hypothèses!B10 | D26: =ROUND(E25*Hypothèses!$B$7,0) | E26: =E25+C26-D26 | F26: =E26*Hypothèses!$B$6 | G26: =C26*Hypothèses!$B$24 | H26: =E26*Hypothèses!$B$25 | I26: =Hypothèses!$B$21 | J26: =F26-G26-H26-I26 | K26: =K25+J26 | M26: =Hypothèses!B11 | N26: =ROUND(O25*Hypothèses!$B$7,0) | O26: =O25+M26-N26 | P26: =O26*Hypothèses!$B$6 | Q26: =M26*Hypothèses!$B$24 | R26: =O26*Hypothèses!$B$25 | S26: =Hypothèses!$B$21 | T26: =P26-Q26-R26-S26 | U26: =U25+T26 | W26: =Hypothèses!B12 | X26: =ROUND(Y25*Hypothèses!$B$7,0) | Y26: =Y25+W26-X26 | Z26: =Y26*Hypothèses!$B$6 | AA26: =W26*Hypothèses!$B$24 | AB26: =Y26*Hypothèses!$B$25 | AC26: =Hypothèses!$B$21 | AD26: =Z26-AA26-AB26-AC26 | AE26: =AE25+AD26
A27: 24 | B27: 46722.208 | C27: =Hypothèses!B10 | D27: =ROUND(E26*Hypothèses!$B$7,0) | E27: =E26+C27-D27 | F27: =E27*Hypothèses!$B$6 | G27: =C27*Hypothèses!$B$24 | H27: =E27*Hypothèses!$B$25 | I27: =Hypothèses!$B$21 | J27: =F27-G27-H27-I27 | K27: =K26+J27 | M27: =Hypothèses!B11 | N27: =ROUND(O26*Hypothèses!$B$7,0) | O27: =O26+M27-N27 | P27: =O27*Hypothèses!$B$6 | Q27: =M27*Hypothèses!$B$24 | R27: =O27*Hypothèses!$B$25 | S27: =Hypothèses!$B$21 | T27: =P27-Q27-R27-S27 | U27: =U26+T27 | W27: =Hypothèses!B12 | X27: =ROUND(Y26*Hypothèses!$B$7,0) | Y27: =Y26+W27-X27 | Z27: =Y27*Hypothèses!$B$6 | AA27: =W27*Hypothèses!$B$24 | AB27: =Y27*Hypothèses!$B$25 | AC27: =Hypothèses!$B$21 | AD27: =Z27-AA27-AB27-AC27 | AE27: =AE26+AD27
A28: 25 | B28: 46753.208 | C28: =Hypothèses!B10 | D28: =ROUND(E27*Hypothèses!$B$7,0) | E28: =E27+C28-D28 | F28: =E28*Hypothèses!$B$6 | G28: =C28*Hypothèses!$B$24 | H28: =E28*Hypothèses!$B$25 | I28: =Hypothèses!$B$21 | J28: =F28-G28-H28-I28 | K28: =K27+J28 | M28: =Hypothèses!B11 | N28: =ROUND(O27*Hypothèses!$B$7,0) | O28: =O27+M28-N28 | P28: =O28*Hypothèses!$B$6 | Q28: =M28*Hypothèses!$B$24 | R28: =O28*Hypothèses!$B$25 | S28: =Hypothèses!$B$21 | T28: =P28-Q28-R28-S28 | U28: =U27+T28 | W28: =Hypothèses!B12 | X28: =ROUND(Y27*Hypothèses!$B$7,0) | Y28: =Y27+W28-X28 | Z28: =Y28*Hypothèses!$B$6 | AA28: =W28*Hypothèses!$B$24 | AB28: =Y28*Hypothèses!$B$25 | AC28: =Hypothèses!$B$21 | AD28: =Z28-AA28-AB28-AC28 | AE28: =AE27+AD28
A29: 26 | B29: 46784.208 | C29: =Hypothèses!B10 | D29: =ROUND(E28*Hypothèses!$B$7,0) | E29: =E28+C29-D29 | F29: =E29*Hypothèses!$B$6 | G29: =C29*Hypothèses!$B$24 | H29: =E29*Hypothèses!$B$25 | I29: =Hypothèses!$B$21 | J29: =F29-G29-H29-I29 | K29: =K28+J29 | M29: =Hypothèses!B11 | N29: =ROUND(O28*Hypothèses!$B$7,0) | O29: =O28+M29-N29 | P29: =O29*Hypothèses!$B$6 | Q29: =M29*Hypothèses!$B$24 | R29: =O29*Hypothèses!$B$25 | S29: =Hypothèses!$B$21 | T29: =P29-Q29-R29-S29 | U29: =U28+T29 | W29: =Hypothèses!B12 | X29: =ROUND(Y28*Hypothèses!$B$7,0) | Y29: =Y28+W29-X29 | Z29: =Y29*Hypothèses!$B$6 | AA29: =W29*Hypothèses!$B$24 | AB29: =Y29*Hypothèses!$B$25 | AC29: =Hypothèses!$B$21 | AD29: =Z29-AA29-AB29-AC29 | AE29: =AE28+AD29
A30: 27 | B30: 46813.208 | C30: =Hypothèses!B10 | D30: =ROUND(E29*Hypothèses!$B$7,0) | E30: =E29+C30-D30 | F30: =E30*Hypothèses!$B$6 | G30: =C30*Hypothèses!$B$24 | H30: =E30*Hypothèses!$B$25 | I30: =Hypothèses!$B$21 | J30: =F30-G30-H30-I30 | K30: =K29+J30 | M30: =Hypothèses!B11 | N30: =ROUND(O29*Hypothèses!$B$7,0) | O30: =O29+M30-N30 | P30: =O30*Hypothèses!$B$6 | Q30: =M30*Hypothèses!$B$24 | R30: =O30*Hypothèses!$B$25 | S30: =Hypothèses!$B$21 | T30: =P30-Q30-R30-S30 | U30: =U29+T30 | W30: =Hypothèses!B12 | X30: =ROUND(Y29*Hypothèses!$B$7,0) | Y30: =Y29+W30-X30 | Z30: =Y30*Hypothèses!$B$6 | AA30: =W30*Hypothèses!$B$24 | AB30: =Y30*Hypothèses!$B$25 | AC30: =Hypothèses!$B$21 | AD30: =Z30-AA30-AB30-AC30 | AE30: =AE29+AD30
A31: 28 | B31: 46844.167 | C31: =Hypothèses!B10 | D31: =ROUND(E30*Hypothèses!$B$7,0) | E31: =E30+C31-D31 | F31: =E31*Hypothèses!$B$6 | G31: =C31*Hypothèses!$B$24 | H31: =E31*Hypothèses!$B$25 | I31: =Hypothèses!$B$21 | J31: =F31-G31-H31-I31 | K31: =K30+J31 | M31: =Hypothèses!B11 | N31: =ROUND(O30*Hypothèses!$B$7,0) | O31: =O30+M31-N31 | P31: =O31*Hypothèses!$B$6 | Q31: =M31*Hypothèses!$B$24 | R31: =O31*Hypothèses!$B$25 | S31: =Hypothèses!$B$21 | T31: =P31-Q31-R31-S31 | U31: =U30+T31 | W31: =Hypothèses!B12 | X31: =ROUND(Y30*Hypothèses!$B$7,0) | Y31: =Y30+W31-X31 | Z31: =Y31*Hypothèses!$B$6 | AA31: =W31*Hypothèses!$B$24 | AB31: =Y31*Hypothèses!$B$25 | AC31: =Hypothèses!$B$21 | AD31: =Z31-AA31-AB31-AC31 | AE31: =AE30+AD31
A32: 29 | B32: 46874.167 | C32: =Hypothèses!B10 | D32: =ROUND(E31*Hypothèses!$B$7,0) | E32: =E31+C32-D32 | F32: =E32*Hypothèses!$B$6 | G32: =C32*Hypothèses!$B$24 | H32: =E32*Hypothèses!$B$25 | I32: =Hypothèses!$B$21 | J32: =F32-G32-H32-I32 | K32: =K31+J32 | M32: =Hypothèses!B11 | N32: =ROUND(O31*Hypothèses!$B$7,0) | O32: =O31+M32-N32 | P32: =O32*Hypothèses!$B$6 | Q32: =M32*Hypothèses!$B$24 | R32: =O32*Hypothèses!$B$25 | S32: =Hypothèses!$B$21 | T32: =P32-Q32-R32-S32 | U32: =U31+T32 | W32: =Hypothèses!B12 | X32: =ROUND(Y31*Hypothèses!$B$7,0) | Y32: =Y31+W32-X32 | Z32: =Y32*Hypothèses!$B$6 | AA32: =W32*Hypothèses!$B$24 | AB32: =Y32*Hypothèses!$B$25 | AC32: =Hypothèses!$B$21 | AD32: =Z32-AA32-AB32-AC32 | AE32: =AE31+AD32
A33: 30 | B33: 46905.167 | C33: =Hypothèses!B10 | D33: =ROUND(E32*Hypothèses!$B$7,0) | E33: =E32+C33-D33 | F33: =E33*Hypothèses!$B$6 | G33: =C33*Hypothèses!$B$24 | H33: =E33*Hypothèses!$B$25 | I33: =Hypothèses!$B$21 | J33: =F33-G33-H33-I33 | K33: =K32+J33 | M33: =Hypothèses!B11 | N33: =ROUND(O32*Hypothèses!$B$7,0) | O33: =O32+M33-N33 | P33: =O33*Hypothèses!$B$6 | Q33: =M33*Hypothèses!$B$24 | R33: =O33*Hypothèses!$B$25 | S33: =Hypothèses!$B$21 | T33: =P33-Q33-R33-S33 | U33: =U32+T33 | W33: =Hypothèses!B12 | X33: =ROUND(Y32*Hypothèses!$B$7,0) | Y33: =Y32+W33-X33 | Z33: =Y33*Hypothèses!$B$6 | AA33: =W33*Hypothèses!$B$24 | AB33: =Y33*Hypothèses!$B$25 | AC33: =Hypothèses!$B$21 | AD33: =Z33-AA33-AB33-AC33 | AE33: =AE32+AD33
A34: 31 | B34: 46935.167 | C34: =Hypothèses!B10 | D34: =ROUND(E33*Hypothèses!$B$7,0) | E34: =E33+C34-D34 | F34: =E34*Hypothèses!$B$6 | G34: =C34*Hypothèses!$B$24 | H34: =E34*Hypothèses!$B$25 | I34: =Hypothèses!$B$21 | J34: =F34-G34-H34-I34 | K34: =K33+J34 | M34: =Hypothèses!B11 | N34: =ROUND(O33*Hypothèses!$B$7,0) | O34: =O33+M34-N34 | P34: =O34*Hypothèses!$B$6 | Q34: =M34*Hypothèses!$B$24 | R34: =O34*Hypothèses!$B$25 | S34: =Hypothèses!$B$21 | T34: =P34-Q34-R34-S34 | U34: =U33+T34 | W34: =Hypothèses!B12 | X34: =ROUND(Y33*Hypothèses!$B$7,0) | Y34: =Y33+W34-X34 | Z34: =Y34*Hypothèses!$B$6 | AA34: =W34*Hypothèses!$B$24 | AB34: =Y34*Hypothèses!$B$25 | AC34: =Hypothèses!$B$21 | AD34: =Z34-AA34-AB34-AC34 | AE34: =AE33+AD34
A35: 32 | B35: 46966.167 | C35: =Hypothèses!B10 | D35: =ROUND(E34*Hypothèses!$B$7,0) | E35: =E34+C35-D35 | F35: =E35*Hypothèses!$B$6 | G35: =C35*Hypothèses!$B$24 | H35: =E35*Hypothèses!$B$25 | I35: =Hypothèses!$B$21 | J35: =F35-G35-H35-I35 | K35: =K34+J35 | M35: =Hypothèses!B11 | N35: =ROUND(O34*Hypothèses!$B$7,0) | O35: =O34+M35-N35 | P35: =O35*Hypothèses!$B$6 | Q35: =M35*Hypothèses!$B$24 | R35: =O35*Hypothèses!$B$25 | S35: =Hypothèses!$B$21 | T35: =P35-Q35-R35-S35 | U35: =U34+T35 | W35: =Hypothèses!B12 | X35: =ROUND(Y34*Hypothèses!$B$7,0) | Y35: =Y34+W35-X35 | Z35: =Y35*Hypothèses!$B$6 | AA35: =W35*Hypothèses!$B$24 | AB35: =Y35*Hypothèses!$B$25 | AC35: =Hypothèses!$B$21 | AD35: =Z35-AA35-AB35-AC35 | AE35: =AE34+AD35
A36: 33 | B36: 46997.167 | C36: =Hypothèses!B10 | D36: =ROUND(E35*Hypothèses!$B$7,0) | E36: =E35+C36-D36 | F36: =E36*Hypothèses!$B$6 | G36: =C36*Hypothèses!$B$24 | H36: =E36*Hypothèses!$B$25 | I36: =Hypothèses!$B$21 | J36: =F36-G36-H36-I36 | K36: =K35+J36 | M36: =Hypothèses!B11 | N36: =ROUND(O35*Hypothèses!$B$7,0) | O36: =O35+M36-N36 | P36: =O36*Hypothèses!$B$6 | Q36: =M36*Hypothèses!$B$24 | R36: =O36*Hypothèses!$B$25 | S36: =Hypothèses!$B$21 | T36: =P36-Q36-R36-S36 | U36: =U35+T36 | W36: =Hypothèses!B12 | X36: =ROUND(Y35*Hypothèses!$B$7,0) | Y36: =Y35+W36-X36 | Z36: =Y36*Hypothèses!$B$6 | AA36: =W36*Hypothèses!$B$24 | AB36: =Y36*Hypothèses!$B$25 | AC36: =Hypothèses!$B$21 | AD36: =Z36-AA36-AB36-AC36 | AE36: =AE35+AD36
A37: 34 | B37: 47027.167 | C37: =Hypothèses!B10 | D37: =ROUND(E36*Hypothèses!$B$7,0) | E37: =E36+C37-D37 | F37: =E37*Hypothèses!$B$6 | G37: =C37*Hypothèses!$B$24 | H37: =E37*Hypothèses!$B$25 | I37: =Hypothèses!$B$21 | J37: =F37-G37-H37-I37 | K37: =K36+J37 | M37: =Hypothèses!B11 | N37: =ROUND(O36*Hypothèses!$B$7,0) | O37: =O36+M37-N37 | P37: =O37*Hypothèses!$B$6 | Q37: =M37*Hypothèses!$B$24 | R37: =O37*Hypothèses!$B$25 | S37: =Hypothèses!$B$21 | T37: =P37-Q37-R37-S37 | U37: =U36+T37 | W37: =Hypothèses!B12 | X37: =ROUND(Y36*Hypothèses!$B$7,0) | Y37: =Y36+W37-X37 | Z37: =Y37*Hypothèses!$B$6 | AA37: =W37*Hypothèses!$B$24 | AB37: =Y37*Hypothèses!$B$25 | AC37: =Hypothèses!$B$21 | AD37: =Z37-AA37-AB37-AC37 | AE37: =AE36+AD37
A38: 35 | B38: 47058.167 | C38: =Hypothèses!B10 | D38: =ROUND(E37*Hypothèses!$B$7,0) | E38: =E37+C38-D38 | F38: =E38*Hypothèses!$B$6 | G38: =C38*Hypothèses!$B$24 | H38: =E38*Hypothèses!$B$25 | I38: =Hypothèses!$B$21 | J38: =F38-G38-H38-I38 | K38: =K37+J38 | M38: =Hypothèses!B11 | N38: =ROUND(O37*Hypothèses!$B$7,0) | O38: =O37+M38-N38 | P38: =O38*Hypothèses!$B$6 | Q38: =M38*Hypothèses!$B$24 | R38: =O38*Hypothèses!$B$25 | S38: =Hypothèses!$B$21 | T38: =P38-Q38-R38-S38 | U38: =U37+T38 | W38: =Hypothèses!B12 | X38: =ROUND(Y37*Hypothèses!$B$7,0) | Y38: =Y37+W38-X38 | Z38: =Y38*Hypothèses!$B$6 | AA38: =W38*Hypothèses!$B$24 | AB38: =Y38*Hypothèses!$B$25 | AC38: =Hypothèses!$B$21 | AD38: =Z38-AA38-AB38-AC38 | AE38: =AE37+AD38
A39: 36 | B39: 47088.208 | C39: =Hypothèses!B10 | D39: =ROUND(E38*Hypothèses!$B$7,0) | E39: =E38+C39-D39 | F39: =E39*Hypothèses!$B$6 | G39: =C39*Hypothèses!$B$24 | H39: =E39*Hypothèses!$B$25 | I39: =Hypothèses!$B$21 | J39: =F39-G39-H39-I39 | K39: =K38+J39 | M39: =Hypothèses!B11 | N39: =ROUND(O38*Hypothèses!$B$7,0) | O39: =O38+M39-N39 | P39: =O39*Hypothèses!$B$6 | Q39: =M39*Hypothèses!$B$24 | R39: =O39*Hypothèses!$B$25 | S39: =Hypothèses!$B$21 | T39: =P39-Q39-R39-S39 | U39: =U38+T39 | W39: =Hypothèses!B12 | X39: =ROUND(Y38*Hypothèses!$B$7,0) | Y39: =Y38+W39-X39 | Z39: =Y39*Hypothèses!$B$6 | AA39: =W39*Hypothèses!$B$24 | AB39: =Y39*Hypothèses!$B$25 | AC39: =Hypothèses!$B$21 | AD39: =Z39-AA39-AB39-AC39 | AE39: =AE38+AD39
A40: RÉSUMÉ ANNUEL
...

Sheet Monte Carlo
A1: SIMULATION MONTE CARLO — 1 000 SIMULATIONS | Variables : ARPU ~ N(42, 4$) | Churn ~ N(2.5%, 0.5%) | Croissance = 120/mois (Base)
A2: Statistique | B2: Moy. | C2: Médiane | D2: Éc.-type | E2: P10 | F2: P25 | G2: P75 | H2: P90 | I2: Min | J2: Max
A3: Revenus An 1 ($) | B3: 362988 | C3: 362484 | D3: 35016 | E3: 317416 | F3: 339494 | G3: 387081 | H3: 408064 | I3: 239507 | J3: 475538
A4: Revenus An 3 ($) | B4: 1298592 | C4: 1299927 | D4: 151179 | E4: 1106621 | F4: 1196925 | G4: 1396797 | H4: 1495097 | I4: 809322 | J4: 1799043
A5: EBITDA An 1 ($) | B5: 55831 | C5: 55681 | D5: 34750 | E5: 10589 | F5: 32479 | G5: 80158 | H5: 100738 | I5: -66189 | J5: 166914
A6: EBITDA An 3 ($) | B6: 812209 | C6: 811988 | D6: 142242 | E6: 631313 | F6: 715973 | G6: 902086 | H6: 998265 | I6: 341618 | J6: 1292747
A7: EBITDA Total 3 ans ($) | B7: 1357805 | C7: 1353374 | D7: 266093 | E7: 1014995 | F7: 1182936 | G7: 1533613 | H7: 1709779 | I7: 450589 | J7: 2253941
A8: Abonnés fin An 3 | B8: 2892 | C8: 2872 | D8: 215 | E8: 2644 | F8: 2749 | G8: 3031 | H8: 3175 | I8: 2149 | J8: 3692
A10: Probabilités clés
A11: Probabilité d'atteindre le seuil de rentabilité (36 mois) | B11: 100.0%
A12: Mois de rentabilité moyen (si atteint) | B12: Mois 5.6
A13: Probabilité EBITDA An 3 positif | B13: 100.0%
A14: Probabilité EBITDA cumulatif positif (3 ans) | B14: 100.0%
A16: Distribution — EBITDA An 3 | B16: Fréquence | C16: % cumulatif
A17: 300k$ à 350k$ | B17: 1 | C17: 0.1%
A18: 350k$ à 400k$ | B18: 0 | C18: 0.1%
A19: 400k$ à 450k$ | B19: 4 | C19: 0.5%
A20: 450k$ à 500k$ | B20: 11 | C20: 1.6%
A21: 500k$ à 550k$ | B21: 15 | C21: 3.1%
A22: 550k$ à 600k$ | B22: 30 | C22: 6.1%
A23: 600k$ à 650k$ | B23: 67 | C23: 12.8%
A24: 650k$ à 700k$ | B24: 90 | C24: 21.8%
A25: 700k$ à 750k$ | B25: 117 | C25: 33.5%
A26: 750k$ à 800k$ | B26: 132 | C26: 46.7%
A27: 800k$ à 850k$ | B27: 148 | C27: 61.5%
A28: 850k$ à 900k$ | B28: 129 | C28: 74.4%
... A36: 1250k$ à 1300k$ | B36: 1 | C36: 100.0%
A38: Échantillon (20 premières simulations) | B38: ARPU sim. | C38: Churn sim. | D38: Rev. An 1 | E38: Rev. An 3 | F38: EBITDA An 1 | G38: EBITDA An 3 | H38: Rentab. (mois)
A39: Simulation 1 | B39: 42.56 | C39: 0.034 | D39: 358505 | E39: 1173738 | F39: 53513 | G39: 715498 | H39: 6
A40: Simulation 2 | B40: 38.48 | C40: 0.026 | D40: 332945 | E40: 1172503 | F40: 26129 | G40: 691151 | H40: 6
A41: Simulation 3 | B41: 42.98 | C41: 0.022 | D41: 378043 | E41: 1391260 | F41: 70083 | G41: 894724 | H41: 5
A42: Simulation 4 | B42: 40.61 | C42: 0.026 | D42: 352477 | E42: 1245568 | F42: 45437 | G42: 762584 | H42: 6
A43: Simulation 5 | B43: 44.45 | C43: 0.021 | D43: 391239 | E43: 1443654 | F43: 83223 | G43: 946222 | H43: 5
A44: Simulation 6 | B44: 44.99 | C44: 0.023 | D44: 393594 | E44: 1425539 | F44: 86010 | G44: 934467 | H44: 5
A45: Simulation 7 | B45: 40 | C45: 0.025 | D45: 347704 | E45: 1235767 | F45: 40568 | G45: 751031 | H45: 6
A46: Simulation 8 | B46: 42.23 | C46: 0.017 | D46: 378147 | E46: 1460474 | F46: 68915 | G46: 946218 | H46: 5
A47: Simulation 9 | B47: 47.91 | C47: 0.019 | D47: 424366 | E47: 1598871 | F47: 115902 | G47: 1094279 | H47: 5
A48: Simulation 10 | B48: 47.37 | C48: 0.023 | D48: 414960 | E48: 1512190 | F48: 107280 | G48: 1019206 | H48: 5
A49: Simulation 11 | B49: 41.64 | C49: 0.029 | D49: 356124 | E49: 1218307 | F49: 50100 | G49: 746627 | H49: 6
A50: Simulation 12 | B50: 42.85 | C50: 0.029 | D50: 367067 | E50: 1259863 | F50: 60931 | G50: 787031 | H50: 5
...

Sheet Sensibilité Prix
A1: ANALYSE DE SENSIBILITÉ — ARPU (40$ / 45$ / 50$) × CROISSANCE (50 / 120 / 250 abonnés/mois)
A3: REVENUS ANNUELS — ANNÉE 1
A4: Croissance \ ARPU | B4: $40/mois | C4: $45/mois | D4: $50/mois
A5: Pessimiste (50/mois) | B5: 148160 | C5: 166680 | D5: 185200
A6: Base (120/mois) | B6: 347720 | C6: 391185 | D6: 434650
A7: Optimiste (250/mois) | B7: 717800 | C7: 807525 | D7: 897250
A10: REVENUS ANNUELS — ANNÉE 3
A11: Croissance \ ARPU | B11: $40/mois | C11: $45/mois | D11: $50/mois
A12: Pessimiste (50/mois) | B12: 518440 | C12: 583245 | D12: 648050
A13: Base (120/mois) | B13: 1238920 | C13: 1393785 | D13: 1548650
A14: Optimiste (250/mois) | B14: 2576240 | C14: 2898270 | D14: 3220300
A17: EBITDA ANNUEL — ANNÉE 3
A18: Croissance \ ARPU | B18: $40/mois | C18: $45/mois | D18: $50/mois
A19: Pessimiste (50/mois) | B19: 189752 | C19: 254557 | D19: 319362
A20: Base (120/mois) | B20: 753536 | C20: 908401 | D20: 1063266
A21: Optimiste (250/mois) | B21: 1799992 | C21: 2122022 | D21: 2444052
A24: MOIS DE RENTABILITÉ (seuil de rentabilité)
A25: Croissance \ ARPU | B25: $40/mois | C25: $45/mois | D25: $50/mois
A26: Pessimiste (50/mois) | B26: 14 | C26: 12 | D26: 10
A27: Base (120/mois) | B27: 6 | C27: 5 | D27: 4
A28: Optimiste (250/mois) | B28: 3 | C28: 3 | D28: 3
A30: 🟢 Vert = Meilleur résultat dans la matrice 🔴 Rouge = Pire résultat / objectif non atteint 🟡 Jaune = Intermédiaire Paramètres fixes : Churn=2.5%, Abonnés initiaux=13, Coûts fixes=$18 000/mois
